<sdf version="1.6">
	<model name="musc_le">
		<link name="base">
			<kinematic>true</kinematic>
			<self_collide>false</self_collide>
			<pose frame="">0.23957826975460578 0.301639778486056 -0.0040404461598430655 0.0 -0.0 0.0</pose>
			<inertial>
				<pose frame="">0.0 0.0 0.0 0 0 0</pose>
				<mass>1.7736941745779755</mass>
				<inertia>
					<ixx>0.26644336870054436</ixx>
					<ixy>-0.12844889813594437</ixy>
					<ixz>0.0007876258706259874</ixz>
					<iyy>0.12328607350226468</iyy>
					<iyz>0.001009493929327395</iyz>
					<izz>0.3889425825854345</izz>
				</inertia>
			</inertial>
			<collision name="base_collision">
				<geometry>
					<mesh>
						<uri>model://musc_le/meshes/collisions/base.dae</uri>
						<scale>0.001 0.001 0.001</scale>
					</mesh>
				</geometry>
			</collision>
			<visual name="base_visual">
				<geometry>
					<mesh>
						<uri>model://musc_le/meshes/visuals/base.dae</uri>
						<scale>0.001 0.001 0.001</scale>
					</mesh>
				</geometry>
			</visual>
		</link>
		<link name="lower_arm">
			<self_collide>false</self_collide>
			<pose frame="">0.23903912786569176 0.3020852713062623 0.26729174484446844 0.0 -0.0 0.0</pose>
			<inertial>
				<pose frame="">0.0 0.0 0.0 0 0 0</pose>
				<mass>1.6629267585832319</mass>
				<inertia>
					<ixx>0.11962789096363666</ixx>
					<ixy>-0.048124291773881854</ixy>
					<ixz>-0.04440482012156901</ixz>
					<iyy>0.09622603986972515</iyy>
					<iyz>-0.056339575354820516</iyz>
					<izz>0.09920838157250772</izz>
				</inertia>
			</inertial>
			<collision name="lower_arm_collision">
				<geometry>
					<mesh>
						<uri>model://musc_le/meshes/collisions/lower_arm.dae</uri>
						<scale>0.001 0.001 0.001</scale>
					</mesh>
				</geometry>
			</collision>
			<visual name="lower_arm_visual">
				<geometry>
					<mesh>
						<uri>model://musc_le/meshes/visuals/lower_arm.dae</uri>
						<scale>0.001 0.001 0.001</scale>
					</mesh>
				</geometry>
			</visual>
		</link>
		<link name="upper_arm">
			<self_collide>false</self_collide>
			<pose frame="">0.24047286580334848 0.2964623740503764 0.5988889249748395 0.0 -0.0 0.0</pose>
			<inertial>
				<pose frame="">0.0 0.0 0.0 0 0 0</pose>
				<mass>0.19546573395199657</mass>
				<inertia>
					<ixx>0.09875572585780393</ixx>
					<ixy>-0.013938850255772264</ixy>
					<ixz>-0.029857585152300914</ixz>
					<iyy>0.09288624160612241</iyy>
					<iyz>-0.036797983975456514</iyz>
					<izz>0.028511074078668243</izz>
				</inertia>
			</inertial>
			<collision name="upper_arm_collision">
				<geometry>
					<mesh>
						<uri>model://musc_le/meshes/collisions/upper_arm.dae</uri>
						<scale>0.001 0.001 0.001</scale>
					</mesh>
				</geometry>
			</collision>
			<visual name="upper_arm_visual">
				<geometry>
					<mesh>
						<uri>model://musc_le/meshes/visuals/upper_arm.dae</uri>
						<scale>0.001 0.001 0.001</scale>
					</mesh>
				</geometry>
			</visual>
		</link>
		<link name='ball'>
      <inertial>
        <mass>1.0117872</mass>
        <inertia>
          <ixx>1.257e-05</ixx>
          <ixy>0</ixy>
          <ixz>0</ixz>
          <iyy>1.257e-05</iyy>
          <iyz>0</iyz>
          <izz>1.257e-05</izz>
        </inertia>
        <pose frame=''>0 0 0 0 -0 0</pose>
      </inertial>
      <pose frame=''>0.238225 0.295141 0.900279 0 -0 0</pose>
      <gravity>1</gravity>
      <self_collide>0</self_collide>
      <kinematic>0</kinematic>
      <enable_wind>0</enable_wind>
      <visual name='visual'>
        <pose frame=''>0 0 0 0 -0 0</pose>
        <geometry>
          <sphere>
            <radius>0.0516307</radius>
          </sphere>
        </geometry>
        <material>
          <lighting>1</lighting>
          <script>
            <uri>file://media/materials/scripts/gazebo.material</uri>
            <name>Gazebo/Grey</name>
          </script>
          <shader type='vertex'>
            <normal_map>__default__</normal_map>
          </shader>
          <emissive>0 0 0 1</emissive>
        </material>
        <transparency>0</transparency>
        <cast_shadows>1</cast_shadows>
      </visual>
      <collision name='collision'>
        <laser_retro>0</laser_retro>
        <max_contacts>10</max_contacts>
        <pose frame=''>0 0 0 0 -0 0</pose>
        <geometry>
          <sphere>
            <radius>0.051631</radius>
          </sphere>
        </geometry>
        <surface>
          <friction>
            <ode>
              <mu>1</mu>
              <mu2>1</mu2>
              <fdir1>0 0 0</fdir1>
              <slip1>0</slip1>
              <slip2>0</slip2>
            </ode>
            <torsional>
              <coefficient>1</coefficient>
              <patch_radius>0</patch_radius>
              <surface_radius>0</surface_radius>
              <use_patch_radius>1</use_patch_radius>
              <ode>
                <slip>0</slip>
              </ode>
            </torsional>
          </friction>
          <bounce>
            <restitution_coefficient>0</restitution_coefficient>
            <threshold>1e+06</threshold>
          </bounce>
          <contact>
            <collide_without_contact>0</collide_without_contact>
            <collide_without_contact_bitmask>1</collide_without_contact_bitmask>
            <collide_bitmask>1</collide_bitmask>
            <ode>
              <soft_cfm>0</soft_cfm>
              <soft_erp>0.2</soft_erp>
              <kp>1e+13</kp>
              <kd>1</kd>
              <max_vel>0.01</max_vel>
              <min_depth>0</min_depth>
            </ode>
            <bullet>
              <split_impulse>1</split_impulse>
              <split_impulse_penetration_threshold>-0.01</split_impulse_penetration_threshold>
              <soft_cfm>0</soft_cfm>
              <soft_erp>0.2</soft_erp>
              <kp>1e+13</kp>
              <kd>1</kd>
            </bullet>
          </contact>
        </surface>
      </collision>
    </link>
		<link name='cricket_ball_5000g'>
		<pose frame=''>0.238225 0.295141 0.880279 0 -0 0</pose>
		<inertial>
			<mass>5</mass>
			<inertia>
				<ixx>0.0028125</ixx>
				<ixy>0</ixy>
				<ixz>0</ixz>
				<iyy>0.0028125</iyy>
				<iyz>0</iyz>
				<izz>0.0028125</izz>
			</inertia>
			<pose frame=''>0 0 0 0 -0 0</pose>
		</inertial>
		<velocity_decay>
			<linear>0</linear>
			<angular>0.005</angular>
		</velocity_decay>
		<self_collide>0</self_collide>
		<enable_wind>0</enable_wind>
		<kinematic>0</kinematic>
		<gravity>1</gravity>
		<visual name='visual'>
			<geometry>
				<sphere>
					<radius>0.0375</radius>
				</sphere>
			</geometry>
			<material>
				<script>
					<uri>file://media/materials/scripts/gazebo.material</uri>
					<name>Gazebo/Red</name>
				</script>
				<shader type='vertex'>
					<normal_map>__default__</normal_map>
				</shader>
				<ambient>1 0 0 1</ambient>
				<diffuse>1 0 0 1</diffuse>
				<specular>0.1 0.1 0.1 1</specular>
				<emissive>0 0 0 1</emissive>
			</material>
			<pose frame=''>0 0 0 0 -0 0</pose>
			<transparency>0</transparency>
			<cast_shadows>1</cast_shadows>
		</visual>
		<collision name='collision'>
			<laser_retro>0</laser_retro>
			<max_contacts>10</max_contacts>
			<pose frame=''>0 0 0 0 -0 0</pose>
			<geometry>
				<sphere>
					<radius>0.0375</radius>
				</sphere>
			</geometry>
			<surface>
				<friction>
					<ode>
						<mu>1</mu>
						<mu2>1</mu2>
						<fdir1>0 0 0</fdir1>
						<slip1>0</slip1>
						<slip2>0</slip2>
					</ode>
					<torsional>
						<coefficient>1</coefficient>
						<patch_radius>0</patch_radius>
						<surface_radius>0.01</surface_radius>
						<use_patch_radius>0</use_patch_radius>
						<ode>
							<slip>0</slip>
						</ode>
					</torsional>
				</friction>
				<bounce>
					<restitution_coefficient>0</restitution_coefficient>
					<threshold>1e+06</threshold>
				</bounce>
				<contact>
					<collide_without_contact>0</collide_without_contact>
					<collide_without_contact_bitmask>1</collide_without_contact_bitmask>
					<collide_bitmask>1</collide_bitmask>
					<ode>
						<soft_cfm>0</soft_cfm>
						<soft_erp>0.2</soft_erp>
						<kp>100000</kp>
						<kd>100</kd>
						<max_vel>100</max_vel>
						<min_depth>0.001</min_depth>
					</ode>
					<bullet>
						<split_impulse>1</split_impulse>
						<split_impulse_penetration_threshold>-0.01</split_impulse_penetration_threshold>
						<soft_cfm>0</soft_cfm>
						<soft_erp>0.2</soft_erp>
						<kp>100000</kp>
						<kd>100</kd>
					</bullet>
				</contact>
			</surface>
		</collision>
	</link>
	<link name='cricket_ball_2000g'>
      <pose frame=''>0.238225 0.295141 0.880279 0 -0 0</pose>
      <inertial>
        <mass>2</mass>
        <inertia>
          <ixx>0.001125</ixx>
          <ixy>0</ixy>
          <ixz>0</ixz>
          <iyy>0.001125</iyy>
          <iyz>0</iyz>
          <izz>0.001125</izz>
        </inertia>
        <pose frame=''>0 0 0 0 -0 0</pose>
      </inertial>
      <velocity_decay>
        <linear>0</linear>
        <angular>0.005</angular>
      </velocity_decay>
      <self_collide>0</self_collide>
      <enable_wind>0</enable_wind>
      <kinematic>0</kinematic>
      <gravity>1</gravity>
      <visual name='visual'>
        <geometry>
          <sphere>
            <radius>0.0375</radius>
          </sphere>
        </geometry>
        <material>
          <script>
            <uri>file://media/materials/scripts/gazebo.material</uri>
            <name>Gazebo/Red</name>
          </script>
          <shader type='vertex'>
            <normal_map>__default__</normal_map>
          </shader>
          <ambient>1 0 0 1</ambient>
          <diffuse>1 0 0 1</diffuse>
          <specular>0.1 0.1 0.1 1</specular>
          <emissive>0 0 0 1</emissive>
        </material>
        <pose frame=''>0 0 0 0 -0 0</pose>
        <transparency>0</transparency>
        <cast_shadows>1</cast_shadows>
      </visual>
      <collision name='collision'>
        <laser_retro>0</laser_retro>
        <max_contacts>10</max_contacts>
        <pose frame=''>0 0 0 0 -0 0</pose>
        <geometry>
          <sphere>
            <radius>0.0375</radius>
          </sphere>
        </geometry>
        <surface>
          <friction>
            <ode>
              <mu>1</mu>
              <mu2>1</mu2>
              <fdir1>0 0 0</fdir1>
              <slip1>0</slip1>
              <slip2>0</slip2>
            </ode>
            <torsional>
              <coefficient>1</coefficient>
              <patch_radius>0</patch_radius>
              <surface_radius>0.01</surface_radius>
              <use_patch_radius>0</use_patch_radius>
              <ode>
                <slip>0</slip>
              </ode>
            </torsional>
          </friction>
          <bounce>
            <restitution_coefficient>0</restitution_coefficient>
            <threshold>1e+06</threshold>
          </bounce>
          <contact>
            <collide_without_contact>0</collide_without_contact>
            <collide_without_contact_bitmask>1</collide_without_contact_bitmask>
            <collide_bitmask>1</collide_bitmask>
            <ode>
              <soft_cfm>0</soft_cfm>
              <soft_erp>0.2</soft_erp>
              <kp>100000</kp>
              <kd>100</kd>
              <max_vel>100</max_vel>
              <min_depth>0.001</min_depth>
            </ode>
            <bullet>
              <split_impulse>1</split_impulse>
              <split_impulse_penetration_threshold>-0.01</split_impulse_penetration_threshold>
              <soft_cfm>0</soft_cfm>
              <soft_erp>0.2</soft_erp>
              <kp>100000</kp>
              <kd>100</kd>
            </bullet>
          </contact>
        </surface>
      </collision>
    </link>
		<link name='cricket_ball_200g'>
      <pose frame=''>0.238225 0.295141 0.880279 0 -0 0</pose>
      <inertial>
        <mass>0.2</mass>
        <inertia>
          <ixx>0.0001125</ixx>
          <ixy>0</ixy>
          <ixz>0</ixz>
          <iyy>0.0001125</iyy>
          <iyz>0</iyz>
          <izz>0.0001125</izz>
        </inertia>
        <pose frame=''>0 0 0 0 -0 0</pose>
      </inertial>
      <velocity_decay>
        <linear>0</linear>
        <angular>0.005</angular>
      </velocity_decay>
      <self_collide>0</self_collide>
      <enable_wind>0</enable_wind>
      <kinematic>0</kinematic>
      <gravity>1</gravity>
      <visual name='visual'>
        <geometry>
          <sphere>
            <radius>0.0375</radius>
          </sphere>
        </geometry>
        <material>
          <script>
            <uri>file://media/materials/scripts/gazebo.material</uri>
            <name>Gazebo/Red</name>
          </script>
          <shader type='vertex'>
            <normal_map>__default__</normal_map>
          </shader>
        </material>
        <pose frame=''>0 0 0 0 -0 0</pose>
        <transparency>0</transparency>
        <cast_shadows>1</cast_shadows>
      </visual>
      <collision name='collision'>
        <laser_retro>0</laser_retro>
        <max_contacts>10</max_contacts>
        <pose frame=''>0 0 0 0 -0 0</pose>
        <geometry>
          <sphere>
            <radius>0.0375</radius>
          </sphere>
        </geometry>
        <surface>
          <friction>
            <ode>
              <mu>1</mu>
              <mu2>1</mu2>
              <fdir1>0 0 0</fdir1>
              <slip1>0</slip1>
              <slip2>0</slip2>
            </ode>
            <torsional>
              <coefficient>1</coefficient>
              <patch_radius>0</patch_radius>
              <surface_radius>0.01</surface_radius>
              <use_patch_radius>0</use_patch_radius>
              <ode>
                <slip>0</slip>
              </ode>
            </torsional>
          </friction>
          <bounce>
            <restitution_coefficient>0</restitution_coefficient>
            <threshold>1e+06</threshold>
          </bounce>
          <contact>
            <collide_without_contact>0</collide_without_contact>
            <collide_without_contact_bitmask>1</collide_without_contact_bitmask>
            <collide_bitmask>1</collide_bitmask>
            <ode>
              <soft_cfm>0</soft_cfm>
              <soft_erp>0.2</soft_erp>
              <kp>100000</kp>
              <kd>100</kd>
              <max_vel>100</max_vel>
              <min_depth>0.001</min_depth>
            </ode>
            <bullet>
              <split_impulse>1</split_impulse>
              <split_impulse_penetration_threshold>-0.01</split_impulse_penetration_threshold>
              <soft_cfm>0</soft_cfm>
              <soft_erp>0.2</soft_erp>
              <kp>100000</kp>
              <kd>100</kd>
            </bullet>
          </contact>
        </surface>
      </collision>
    </link>
		<joint name="upper_joint" type="revolute">
			<parent>lower_arm</parent>
			<child>upper_arm</child>
			<pose frame="">-0.004822865803349181 -3.31893305476072e-05 -0.137753391072036 0 0 0</pose>
			<axis>
				<xyz>1.0000000000000002 -8.881784197001256e-16 -9.575673587391985e-16</xyz>
				<limit>
					<!-- <lower>-1.3962634015954636</lower>
					<upper>1.3962634015954636</upper> -->
					<lower>-0.647</lower>
					<upper>0.647</upper>
				</limit>
				<use_parent_model_frame>0</use_parent_model_frame>
			</axis>
		</joint>
		<joint name="lower_joint" type="revolute">
			<parent>base</parent>
			<child>lower_arm</child>
			<pose frame="">-0.016839127865691774 -8.52713062622712e-05 -0.2296310846758187 0 0 0</pose>
			<axis>
				<xyz>-1.0 2.3876466213831606e-16 7.771561172376107e-16</xyz>
				<limit>
					<lower>-0.8727</lower>
					<upper>0.8727</upper>
				</limit>
				<use_parent_model_frame>0</use_parent_model_frame>
			</axis>
		</joint>
		<joint name='ball_joint' type='fixed'>

		 <parent>upper_arm</parent>
		 <child>cricket_ball_200g</child>
		 <pose frame=''>0 0 0 0 -0 0</pose>
	 </joint>
		<plugin filename="libcardsflow_gazebo_plugin.so" name="cardsflow_gazebo_plugin">
		</plugin>
	</model>
</sdf>
